# Error

## Error

Error are thrown when runtime error occurs. The developer can also define custom `Error{:js}` objects.

To create a an `Error{:js}` object we use the `Error(){:js}` constructor.

```js copy
const myError = Error('Oops!')

console.log(myError.toString()) // Error: Oops!
```

You may also preceed the `Error(){:js}` constructor with the `new{:js}` keyword. Using `new{:js}` is optional.

```js copy
const errWithNew = new Error('Oops!')
const errWithoutNew = Error('Oops!')

console.log(errWithNew.toString()) // Error: Oops!
console.log(errWithoutNew.toString()) // Error: Oops!
```

## Properties

### message

For user-created Error objects, this is the string provided as the constructor's first argument.

```js copy
const myError = Error(`Hi, I'm an error message! You will hate me.`)

console.log(myError.message)
// "Hi, I'm an error message! You will hate me."
```

### name

This is determined by the constructor function.

```js copy
const err1 = Error('Oops!')
const err2 = RangeError('Oops!')
const err3 = ReferenceError('Oops!')

console.log(err1.name) // Error
console.log(err2.name) // RangeError
console.log(err3.name) // ReferenceError
```

### cause

Indicates the reason why the current error is thrown â€” usually another caught error. For user-created `Error{:js}` objects, this is the value provided as the cause property of the constructor's second argument.

```js copy
function betweenZeroAndOne(number) {
  try {
    if (number < 0) {
      // Check failed. Explain the error.
      throw RangeError('Provided a negative number.')
    }
    if (number > 1) {
      // Check failed. Explain the error.
      throw RangeError('Provided a number greater than one.')
    }
  } catch (error) {
    // Rethrow the error to provide more context to the
    // error message.
    // In this case we blame somebody then provide a cause.
    throw Error('You did something wrong.', { cause: error })
  }
}

try {
  betweenZeroAndOne(5)
} catch (error) {
  console.error({
    error: error.message,
    cause: error.cause.message
  })
}
/*
{
  error: 'You did something wrong.',
  cause: 'Provided a number greater than one.'
}
*/
```

### stack

A non-standard property for a stack trace. The section of the error informs the developer about where the error is coming from in the code.

```js copy
const myError = Error('Oops!')

console.log(myError.stack)

/*
Error: Oops!
    at Object.<anonymous> (/path/to/file.js:1:17)
    at Module._compile (node:internal/modules/cjs/loader:1218:14)
    at Module._extensions..js (node:internal/modules/cjs/loader:1272:10)
    at Module.load (node:internal/modules/cjs/loader:1081:32)
    at Module._load (node:internal/modules/cjs/loader:922:12)
    at Function.executeUserEntryPoint [as runMain] (node:internal/modules/run_main:82:12)
    at node:internal/main/run_main_module:23:47
 */
```

### toString

Returns a string representing the specified object. Overrides the Object.prototype.toString() method.

```js copy
const myError = Error('Oops, something went wrong!')

console.log(myError.toString())
// 'Oops, something went wrong!'
```

## Error Types

### RangeError

Creates an instance representing an error that occurs when a numeric variable or parameter is outside its valid range.

```js copy
function allowPositiveNumbers(number) {
  if (number < 0) {
    throw RangeError('The number must be greater than 0.')
  }
}

try {
  allowPositiveNumbers(-5)
} catch (error) {
  if (error instanceof RangeError) {
    console.error(error.toString())
    // 'RangeError: The number must be greater than 0.'
  }
}
```

### ReferenceError

Creates an instance representing an error that occurs when de-referencing an invalid reference.

```js copy
try {
  console.log(mySoulMate)
} catch (error) {
  if (error instanceof ReferenceError) {
    console.error(error.toString())
    // 'ReferenceError: mySoulMate is not defined'
  }
}
```

### SyntaxError

Creates an instance representing a syntax error.

```js copy
const theMeaningOfLife = 41 +

// SyntaxError: Unexpected end of input
```

### TypeError

Creates an instance representing an error that occurs when a variable or parameter is not of a valid type.

```js copy
try {
  undefined.toString()
} catch (error) {
  if (error instanceof TypeError) {
    console.error(error.toString())
    // 'TypeError: Cannot read properties of undefined (reading 'toString')'
  }
}
```

### URIError

Creates an instance representing an error that occurs when `encodeURI(){:js}` or `decodeURI(){:js}` are passed invalid parameters.

```js copy
try {
  decodeURIComponent('%5%5%5%5%')
} catch (error) {
  if (error instanceof URIError) {
    console.error(error.toString())
    // 'URIError: URI malformed'
  }
}
```

### AggregateError

Creates an instance representing several errors wrapped in a single error when multiple errors need to be reported by an operation, for example by `Promise.any(){:js}`.

```js copy
Promise.any([Promise.reject(Error('oops!'))]).catch((error) => {
  if (error instanceof AggregateError) {
    console.error(error.toString())
    // 'AggregateError: All promises were rejected'
  }
})
```

## throw

```js copy
const err1 = Error('The patient has died.')

// above has the same functionality as following
const err2 = new Error('The patient has died.')
```
